2020-07-02 23:21:42,311 ERROR: Exception on /user/jenny1 [GET] [in C:\Users\jfeng\AppData\Local\Continuum\miniconda3\envs\datascience\lib\site-packages\flask\app.py:1892]
Traceback (most recent call last):
  File "C:\Users\jfeng\AppData\Local\Continuum\miniconda3\envs\datascience\lib\site-packages\flask\app.py", line 2447, in wsgi_app
    response = self.full_dispatch_request()
  File "C:\Users\jfeng\AppData\Local\Continuum\miniconda3\envs\datascience\lib\site-packages\flask\app.py", line 1952, in full_dispatch_request
    rv = self.handle_user_exception(e)
  File "C:\Users\jfeng\AppData\Local\Continuum\miniconda3\envs\datascience\lib\site-packages\flask\app.py", line 1821, in handle_user_exception
    reraise(exc_type, exc_value, tb)
  File "C:\Users\jfeng\AppData\Local\Continuum\miniconda3\envs\datascience\lib\site-packages\flask\_compat.py", line 39, in reraise
    raise value
  File "C:\Users\jfeng\AppData\Local\Continuum\miniconda3\envs\datascience\lib\site-packages\flask\app.py", line 1950, in full_dispatch_request
    rv = self.dispatch_request()
  File "C:\Users\jfeng\AppData\Local\Continuum\miniconda3\envs\datascience\lib\site-packages\flask\app.py", line 1936, in dispatch_request
    return self.view_functions[rule.endpoint](**req.view_args)
  File "C:\Users\jfeng\AppData\Local\Continuum\miniconda3\envs\datascience\lib\site-packages\flask_login\utils.py", line 272, in decorated_view
    return func(*args, **kwargs)
  File "C:\Users\jfeng\github\flask_mega_project\app\routes.py", line 74, in user
NameError: name 'posts' is not defined
2020-07-02 23:23:04,302 ERROR: Exception on /user/jenny1 [GET] [in C:\Users\jfeng\AppData\Local\Continuum\miniconda3\envs\datascience\lib\site-packages\flask\app.py:1892]
Traceback (most recent call last):
  File "C:\Users\jfeng\AppData\Local\Continuum\miniconda3\envs\datascience\lib\site-packages\flask\app.py", line 2447, in wsgi_app
    response = self.full_dispatch_request()
  File "C:\Users\jfeng\AppData\Local\Continuum\miniconda3\envs\datascience\lib\site-packages\flask\app.py", line 1952, in full_dispatch_request
    rv = self.handle_user_exception(e)
  File "C:\Users\jfeng\AppData\Local\Continuum\miniconda3\envs\datascience\lib\site-packages\flask\app.py", line 1821, in handle_user_exception
    reraise(exc_type, exc_value, tb)
  File "C:\Users\jfeng\AppData\Local\Continuum\miniconda3\envs\datascience\lib\site-packages\flask\_compat.py", line 39, in reraise
    raise value
  File "C:\Users\jfeng\AppData\Local\Continuum\miniconda3\envs\datascience\lib\site-packages\flask\app.py", line 1950, in full_dispatch_request
    rv = self.dispatch_request()
  File "C:\Users\jfeng\AppData\Local\Continuum\miniconda3\envs\datascience\lib\site-packages\flask\app.py", line 1936, in dispatch_request
    return self.view_functions[rule.endpoint](**req.view_args)
  File "C:\Users\jfeng\AppData\Local\Continuum\miniconda3\envs\datascience\lib\site-packages\flask_login\utils.py", line 272, in decorated_view
    return func(*args, **kwargs)
  File "C:\Users\jfeng\github\flask_mega_project\app\routes.py", line 74, in user
NameError: name 'posts' is not defined
2020-07-02 23:25:16,185 ERROR: Exception on /user/jenny1 [GET] [in C:\Users\jfeng\AppData\Local\Continuum\miniconda3\envs\datascience\lib\site-packages\flask\app.py:1892]
Traceback (most recent call last):
  File "C:\Users\jfeng\AppData\Local\Continuum\miniconda3\envs\datascience\lib\site-packages\flask\app.py", line 2447, in wsgi_app
    response = self.full_dispatch_request()
  File "C:\Users\jfeng\AppData\Local\Continuum\miniconda3\envs\datascience\lib\site-packages\flask\app.py", line 1952, in full_dispatch_request
    rv = self.handle_user_exception(e)
  File "C:\Users\jfeng\AppData\Local\Continuum\miniconda3\envs\datascience\lib\site-packages\flask\app.py", line 1821, in handle_user_exception
    reraise(exc_type, exc_value, tb)
  File "C:\Users\jfeng\AppData\Local\Continuum\miniconda3\envs\datascience\lib\site-packages\flask\_compat.py", line 39, in reraise
    raise value
  File "C:\Users\jfeng\AppData\Local\Continuum\miniconda3\envs\datascience\lib\site-packages\flask\app.py", line 1950, in full_dispatch_request
    rv = self.dispatch_request()
  File "C:\Users\jfeng\AppData\Local\Continuum\miniconda3\envs\datascience\lib\site-packages\flask\app.py", line 1936, in dispatch_request
    return self.view_functions[rule.endpoint](**req.view_args)
  File "C:\Users\jfeng\AppData\Local\Continuum\miniconda3\envs\datascience\lib\site-packages\flask_login\utils.py", line 272, in decorated_view
    return func(*args, **kwargs)
  File "C:\Users\jfeng\github\flask_mega_project\app\routes.py", line 74, in user
NameError: name 'posts' is not defined
2020-07-02 23:25:18,121 ERROR: Exception on /user/jenny1 [GET] [in C:\Users\jfeng\AppData\Local\Continuum\miniconda3\envs\datascience\lib\site-packages\flask\app.py:1892]
Traceback (most recent call last):
  File "C:\Users\jfeng\AppData\Local\Continuum\miniconda3\envs\datascience\lib\site-packages\flask\app.py", line 2447, in wsgi_app
    response = self.full_dispatch_request()
  File "C:\Users\jfeng\AppData\Local\Continuum\miniconda3\envs\datascience\lib\site-packages\flask\app.py", line 1952, in full_dispatch_request
    rv = self.handle_user_exception(e)
  File "C:\Users\jfeng\AppData\Local\Continuum\miniconda3\envs\datascience\lib\site-packages\flask\app.py", line 1821, in handle_user_exception
    reraise(exc_type, exc_value, tb)
  File "C:\Users\jfeng\AppData\Local\Continuum\miniconda3\envs\datascience\lib\site-packages\flask\_compat.py", line 39, in reraise
    raise value
  File "C:\Users\jfeng\AppData\Local\Continuum\miniconda3\envs\datascience\lib\site-packages\flask\app.py", line 1950, in full_dispatch_request
    rv = self.dispatch_request()
  File "C:\Users\jfeng\AppData\Local\Continuum\miniconda3\envs\datascience\lib\site-packages\flask\app.py", line 1936, in dispatch_request
    return self.view_functions[rule.endpoint](**req.view_args)
  File "C:\Users\jfeng\AppData\Local\Continuum\miniconda3\envs\datascience\lib\site-packages\flask_login\utils.py", line 272, in decorated_view
    return func(*args, **kwargs)
  File "C:\Users\jfeng\github\flask_mega_project\app\routes.py", line 74, in user
NameError: name 'posts' is not defined
2020-07-02 23:25:20,214 ERROR: Exception on /user/jenny1 [GET] [in C:\Users\jfeng\AppData\Local\Continuum\miniconda3\envs\datascience\lib\site-packages\flask\app.py:1892]
Traceback (most recent call last):
  File "C:\Users\jfeng\AppData\Local\Continuum\miniconda3\envs\datascience\lib\site-packages\flask\app.py", line 2447, in wsgi_app
    response = self.full_dispatch_request()
  File "C:\Users\jfeng\AppData\Local\Continuum\miniconda3\envs\datascience\lib\site-packages\flask\app.py", line 1952, in full_dispatch_request
    rv = self.handle_user_exception(e)
  File "C:\Users\jfeng\AppData\Local\Continuum\miniconda3\envs\datascience\lib\site-packages\flask\app.py", line 1821, in handle_user_exception
    reraise(exc_type, exc_value, tb)
  File "C:\Users\jfeng\AppData\Local\Continuum\miniconda3\envs\datascience\lib\site-packages\flask\_compat.py", line 39, in reraise
    raise value
  File "C:\Users\jfeng\AppData\Local\Continuum\miniconda3\envs\datascience\lib\site-packages\flask\app.py", line 1950, in full_dispatch_request
    rv = self.dispatch_request()
  File "C:\Users\jfeng\AppData\Local\Continuum\miniconda3\envs\datascience\lib\site-packages\flask\app.py", line 1936, in dispatch_request
    return self.view_functions[rule.endpoint](**req.view_args)
  File "C:\Users\jfeng\AppData\Local\Continuum\miniconda3\envs\datascience\lib\site-packages\flask_login\utils.py", line 272, in decorated_view
    return func(*args, **kwargs)
  File "C:\Users\jfeng\github\flask_mega_project\app\routes.py", line 74, in user
NameError: name 'posts' is not defined
2020-07-02 23:25:22,890 ERROR: Exception on /user/jenny1 [GET] [in C:\Users\jfeng\AppData\Local\Continuum\miniconda3\envs\datascience\lib\site-packages\flask\app.py:1892]
Traceback (most recent call last):
  File "C:\Users\jfeng\AppData\Local\Continuum\miniconda3\envs\datascience\lib\site-packages\flask\app.py", line 2447, in wsgi_app
    response = self.full_dispatch_request()
  File "C:\Users\jfeng\AppData\Local\Continuum\miniconda3\envs\datascience\lib\site-packages\flask\app.py", line 1952, in full_dispatch_request
    rv = self.handle_user_exception(e)
  File "C:\Users\jfeng\AppData\Local\Continuum\miniconda3\envs\datascience\lib\site-packages\flask\app.py", line 1821, in handle_user_exception
    reraise(exc_type, exc_value, tb)
  File "C:\Users\jfeng\AppData\Local\Continuum\miniconda3\envs\datascience\lib\site-packages\flask\_compat.py", line 39, in reraise
    raise value
  File "C:\Users\jfeng\AppData\Local\Continuum\miniconda3\envs\datascience\lib\site-packages\flask\app.py", line 1950, in full_dispatch_request
    rv = self.dispatch_request()
  File "C:\Users\jfeng\AppData\Local\Continuum\miniconda3\envs\datascience\lib\site-packages\flask\app.py", line 1936, in dispatch_request
    return self.view_functions[rule.endpoint](**req.view_args)
  File "C:\Users\jfeng\AppData\Local\Continuum\miniconda3\envs\datascience\lib\site-packages\flask_login\utils.py", line 272, in decorated_view
    return func(*args, **kwargs)
  File "C:\Users\jfeng\github\flask_mega_project\app\routes.py", line 74, in user
NameError: name 'posts' is not defined
